[0m02:42:29.327072 [debug] [MainThread]: Sending event: {'category': 'dbt', 'action': 'invocation', 'label': 'start', 'context': [<snowplow_tracker.self_describing_json.SelfDescribingJson object at 0x71d5fd47aa90>, <snowplow_tracker.self_describing_json.SelfDescribingJson object at 0x71d5fd451650>, <snowplow_tracker.self_describing_json.SelfDescribingJson object at 0x71d5fd0cb010>]}


============================== 02:42:29.338774 | 8c540449-edb0-49ea-a79b-b97cb88b64fa ==============================
[0m02:42:29.338774 [info ] [MainThread]: Running with dbt=1.9.0-a1
[0m02:42:29.339864 [debug] [MainThread]: running dbt with arguments {'printer_width': '80', 'indirect_selection': 'eager', 'write_json': 'True', 'log_cache_events': 'False', 'partial_parse': 'True', 'cache_selected_only': 'False', 'warn_error': 'None', 'debug': 'False', 'version_check': 'True', 'log_path': 'logs', 'fail_fast': 'False', 'profiles_dir': '/root/.dbt', 'use_colors': 'True', 'use_experimental_parser': 'False', 'no_print': 'None', 'quiet': 'False', 'log_format': 'default', 'invocation_command': 'dbt ls', 'introspect': 'True', 'warn_error_options': 'WarnErrorOptions(include=[], exclude=[])', 'target_path': 'None', 'static_parser': 'True', 'send_anonymous_usage_stats': 'True'}
[0m02:42:29.340767 [error] [MainThread]: Encountered an error:
Runtime Error
  No dbt_project.yml found at expected path /usr/app/dbt/dbt_project.yml
  Verify that each entry within packages.yml (and their transitive dependencies) contains a file named dbt_project.yml
  
[0m02:42:29.342626 [debug] [MainThread]: Resource report: {"command_name": "list", "command_wall_clock_time": 0.10934208, "process_user_time": 2.553231, "process_kernel_time": 0.336162, "process_mem_max_rss": "84808", "process_out_blocks": "1592", "command_success": false, "process_in_blocks": "0"}
[0m02:42:29.343693 [debug] [MainThread]: Command `dbt ls` failed at 02:42:29.343452 after 0.11 seconds
[0m02:42:29.344449 [debug] [MainThread]: Sending event: {'category': 'dbt', 'action': 'invocation', 'label': 'end', 'context': [<snowplow_tracker.self_describing_json.SelfDescribingJson object at 0x71d5fd0ea990>, <snowplow_tracker.self_describing_json.SelfDescribingJson object at 0x71d5fd0eaa90>, <snowplow_tracker.self_describing_json.SelfDescribingJson object at 0x71d5fd450f10>]}
[0m02:42:29.345229 [debug] [MainThread]: Flushing usage events
[0m02:54:34.482038 [debug] [MainThread]: Sending event: {'category': 'dbt', 'action': 'invocation', 'label': 'start', 'context': [<snowplow_tracker.self_describing_json.SelfDescribingJson object at 0x720cd5456f50>, <snowplow_tracker.self_describing_json.SelfDescribingJson object at 0x720cd57238d0>, <snowplow_tracker.self_describing_json.SelfDescribingJson object at 0x720cd61ccc50>]}


============================== 02:54:34.494172 | df85effa-2b81-4d63-a82d-98e71d4d4259 ==============================
[0m02:54:34.494172 [info ] [MainThread]: Running with dbt=1.9.0-a1
[0m02:54:34.495304 [debug] [MainThread]: running dbt with arguments {'printer_width': '80', 'indirect_selection': 'eager', 'write_json': 'True', 'log_cache_events': 'False', 'partial_parse': 'True', 'cache_selected_only': 'False', 'warn_error': 'None', 'debug': 'False', 'profiles_dir': '/root/.dbt', 'log_path': 'logs', 'version_check': 'True', 'fail_fast': 'False', 'use_colors': 'True', 'use_experimental_parser': 'False', 'no_print': 'None', 'quiet': 'False', 'warn_error_options': 'WarnErrorOptions(include=[], exclude=[])', 'invocation_command': 'dbt deps', 'log_format': 'default', 'static_parser': 'True', 'target_path': 'None', 'introspect': 'True', 'send_anonymous_usage_stats': 'True'}
[0m02:54:34.496427 [error] [MainThread]: Encountered an error:
Runtime Error
  No dbt_project.yml found at expected path /usr/app/dbt/dbt_project.yml
  Verify that each entry within packages.yml (and their transitive dependencies) contains a file named dbt_project.yml
  
[0m02:54:34.498193 [debug] [MainThread]: Resource report: {"command_name": "deps", "command_wall_clock_time": 0.10991303, "process_user_time": 2.696088, "process_kernel_time": 0.248008, "process_mem_max_rss": "84660", "process_out_blocks": "1592", "command_success": false, "process_in_blocks": "0"}
[0m02:54:34.499225 [debug] [MainThread]: Command `dbt deps` failed at 02:54:34.498985 after 0.11 seconds
[0m02:54:34.499923 [debug] [MainThread]: Sending event: {'category': 'dbt', 'action': 'invocation', 'label': 'end', 'context': [<snowplow_tracker.self_describing_json.SelfDescribingJson object at 0x720cd5454d50>, <snowplow_tracker.self_describing_json.SelfDescribingJson object at 0x720cd5454fd0>, <snowplow_tracker.self_describing_json.SelfDescribingJson object at 0x720cd5457790>]}
[0m02:54:34.500918 [debug] [MainThread]: Flushing usage events
